<?xml version="1.0"?>
<robot name="alaris_gripper_finger" xmlns:xacro="http://www.ros.org/wiki/xacro">

<xacro:macro name="alaris_gripper_finger" params="prefix finger_id parent *origin">

    <link name="${prefix}_finger_${finger_id}_bottom_shaft1_link">
        <visual>
            <origin xyz="0 0 0" rpy="0 0 0"/>
            <geometry>
                <mesh filename="package://alaris_gripper_description/meshes/Gripper_Assembly - shaft_3.STL" scale="0.001 0.001 0.001"/>
            </geometry>
            <material name="gray"/>
        </visual>
        <collision>
            <origin xyz="0.0 0.0 0.0" rpy="0 0 0"/>
            <geometry>
                <mesh filename="package://alaris_gripper_description/meshes/Gripper_Assembly - shaft_3.STL" scale="0.001 0.001 0.001"/>
            </geometry>
        </collision>
        <inertial>
            <mass value="0.079" />
            <origin xyz="0 0 0" />
            <inertia ixx="0.003881243" ixy="0.0" ixz="0.0"
                     iyy="0.000498940" iyz="0.0"
                     izz="0.003879257" />
        </inertial>
    </link>

    <joint name="${prefix}_finger_${finger_id}_link1_bottom_shaft1_joint" type="revolute">
        <xacro:insert_block name="origin"/>
        <axis xyz="0 1 0" />
        <limit lower="-0.8" upper="0" effort="10" velocity="10" />
        <parent link="${parent}"/>
        <child link="${prefix}_finger_${finger_id}_bottom_shaft1_link"/>
        <mimic joint="${prefix}_mx28t_worm_joint" multiplier="1"/> 
        <dynamics damping="0.02" friction="0.0" />
    </joint>

    <link name="${prefix}_finger_${finger_id}_link1_revolution_point1"/>

    <joint name="${prefix}_finger_${finger_id}_link1_revolution_point1_joint" type="continuous">
        <origin xyz="0 0 0" rpy="0 0 ${PI/3}"/>
        <axis xyz="0.64 0.36 0" />
        <parent link="${prefix}_finger_${finger_id}_bottom_shaft1_link"/>
        <child link="${prefix}_finger_${finger_id}_link1_revolution_point1"/>
        <mimic joint="${prefix}_finger_${finger_id}_phalanx2_revolution_point_joint" multiplier="0.49"/>
        <dynamics damping="0.02" friction="0.0" />
    </joint>

    <link name="${prefix}_finger_${finger_id}_link1_link">
        <visual>
            <origin xyz="0 0 0" rpy="0 0 0"/>
            <geometry>
                <mesh filename="package://alaris_gripper_description/meshes/Gripper_Assembly - link_1.STL" scale="0.001 0.001 0.001"/>
            </geometry>
            <material name="white"/>
        </visual>
        <collision>
            <origin xyz="0.0 0.0 0.0" rpy="0 0 0"/>
            <geometry>
                <mesh filename="package://alaris_gripper_description/meshes/Gripper_Assembly - link_1.STL" scale="0.001 0.001 0.001"/>
            </geometry>
        </collision>
        <inertial>
            <mass value="0.079" />
            <origin xyz="0 0 0" />
            <inertia ixx="0.003881243" ixy="0.0" ixz="0.0"
                     iyy="0.000498940" iyz="0.0"
                     izz="0.003879257" />
        </inertial>
    </link>

    <joint name="${prefix}_finger_${finger_id}_gear_link_joint" type="fixed">
        <origin xyz="0.0012 -0.0025 -0.001" rpy="0 0 0"/>
        <parent link="${prefix}_finger_${finger_id}_link1_revolution_point1"/>
        <child link="${prefix}_finger_${finger_id}_link1_link"/>
    </joint>

    <link name="${prefix}_finger_${finger_id}_link1_revolution_point2"/>

    <joint name="${prefix}_finger_${finger_id}_link1_revolution_point2_joint" type="continuous">
        <origin xyz="0.01252 -0.0218 -0.0101" rpy="0 0 -${PI/3}"/>
        <axis xyz="0 1 0" />
        <parent link="${prefix}_finger_${finger_id}_link1_link"/>
        <child link="${prefix}_finger_${finger_id}_link1_revolution_point2"/>
        <mimic joint="${prefix}_finger_${finger_id}_phalanx2_revolution_point_joint" multiplier="-0.55"/>
    </joint>

    <link name="${prefix}_finger_${finger_id}_link2_link">
        <visual>
            <origin xyz="0 0 0" rpy="0 0 0"/>
            <geometry>
                <mesh filename="package://alaris_gripper_description/meshes/Gripper_Assembly - link_2.STL" scale="0.001 0.001 0.001"/>
            </geometry>
            <material name="white"/>
        </visual>
        <collision>
            <origin xyz="0.0 0.0 0.0" rpy="0 0 0"/>
            <geometry>
                <mesh filename="package://alaris_gripper_description/meshes/Gripper_Assembly - link_2.STL" scale="0.001 0.001 0.001"/>
            </geometry>
        </collision>
        <inertial>
            <mass value="0.079" />
            <origin xyz="0 0 0" />
            <inertia ixx="0.003881243" ixy="0.0" ixz="0.0"
                     iyy="0.000498940" iyz="0.0"
                     izz="0.003879257" />
        </inertial>
    </link>

    <joint name="${prefix}_finger_${finger_id}_link1_link2_joint" type="fixed">
        <origin xyz="0.0065 0 0.034" rpy="0 0 ${PI/3}"/>
        <parent link="${prefix}_finger_${finger_id}_link1_revolution_point2"/>
        <child link="${prefix}_finger_${finger_id}_link2_link"/>
    </joint>

    <link name="${prefix}_finger_${finger_id}_phalanx1_link">
        <visual>
            <origin xyz="0 0 0" rpy="0 0 0"/>
            <geometry>
                <mesh filename="package://alaris_gripper_description/meshes/Gripper_Assembly - phalanx_1.STL" scale="0.001 0.001 0.001"/>
            </geometry>
            <material name="white"/>
        </visual>
        <collision>
            <origin xyz="0.0 0.0 0.0" rpy="0 0 0"/>
            <geometry>
                <mesh filename="package://alaris_gripper_description/meshes/Gripper_Assembly - phalanx_1.STL" scale="0.001 0.001 0.001"/>
            </geometry>
        </collision>
        <inertial>
            <mass value="0.079" />
            <origin xyz="0 0 0" />
            <inertia ixx="0.003881243" ixy="0.0" ixz="0.0"
                     iyy="0.000498940" iyz="0.0"
                     izz="0.003879257" />
        </inertial>
    </link>

    <joint name="${prefix}_finger_${finger_id}_link1_phalanx1_joint" type="fixed">
        <origin xyz="0.01825 0.00075 0.01925" rpy="0 0 ${PI/3}"/>
        <parent link="${prefix}_finger_${finger_id}_bottom_shaft1_link"/>
        <child link="${prefix}_finger_${finger_id}_phalanx1_link"/>
    </joint>

    <link name="${prefix}_finger_${finger_id}_phalanx2_revolution_point"/>

    <joint name="${prefix}_finger_${finger_id}_phalanx2_revolution_point_joint" type="revolute">
        <origin xyz="0.004 -0.012 0.041" rpy="0 0 -${PI/3}"/>
        <axis xyz="0 1 0" />
        <limit lower="-0.8" upper="0" effort="10" velocity="10" />
        <parent link="${prefix}_finger_${finger_id}_phalanx1_link"/>
        <child link="${prefix}_finger_${finger_id}_phalanx2_revolution_point"/>
        <dynamics damping="0.02" friction="0.0" />
    </joint>

    <link name="${prefix}_finger_${finger_id}_phalanx2_link">
        <visual>
            <origin xyz="0 0 0" rpy="0 0 0"/>
            <geometry>
                <mesh filename="package://alaris_gripper_description/meshes/Gripper_Assembly - phalanx_2.STL" scale="0.001 0.001 0.001"/>
            </geometry>
            <material name="white"/>
        </visual>
        <collision>
            <origin xyz="0.0 0.0 0.0" rpy="0 0 0"/>
            <geometry>
                <mesh filename="package://alaris_gripper_description/meshes/Gripper_Assembly - phalanx_2.STL" scale="0.001 0.001 0.001"/>
            </geometry>
        </collision>
        <inertial>
            <mass value="0.079" />
            <origin xyz="0 0 0" />
            <inertia ixx="0.003881243" ixy="0.0" ixz="0.0"
                     iyy="0.000498940" iyz="0.0"
                     izz="0.003879257" />
        </inertial>
    </link>

    <joint name="${prefix}_finger_${finger_id}_phalanx1_phalanx2_joint" type="fixed">
        <origin xyz="0.013 0.001 0.016" rpy="0 0 ${PI/3}"/>
        <parent link="${prefix}_finger_${finger_id}_phalanx2_revolution_point"/>
        <child link="${prefix}_finger_${finger_id}_phalanx2_link"/>
    </joint>

    <link name="${prefix}_finger_${finger_id}_rubber_phalanx1_link">
        <visual>
            <origin xyz="0 0 0" rpy="0 0 0"/>
            <geometry>
                <mesh filename="package://alaris_gripper_description/meshes/Gripper_Assembly - rubber_phalanx_1.STL" scale="0.001 0.001 0.001"/>
            </geometry>
            <material name="black"/>
        </visual>
        <collision>
            <origin xyz="0.0 0.0 0.0" rpy="0 0 0"/>
            <geometry>
                <mesh filename="package://alaris_gripper_description/meshes/Gripper_Assembly - rubber_phalanx_1.STL" scale="0.001 0.001 0.001"/>
            </geometry>
        </collision>
        <inertial>
            <mass value="0.079" />
            <origin xyz="0 0 0" />
            <inertia ixx="0.003881243" ixy="0.0" ixz="0.0"
                     iyy="0.000498940" iyz="0.0"
                     izz="0.003879257" />
        </inertial>
    </link>

    <joint name="${prefix}_finger_${finger_id}_phalanx1_rubber_joint" type="fixed">
        <origin xyz="-0.003 0.003 0.02" rpy="${PI/3} -${PI/7} ${PI/4}"/>
        <parent link="${prefix}_finger_${finger_id}_phalanx1_link"/>
        <child link="${prefix}_finger_${finger_id}_rubber_phalanx1_link"/>
    </joint>

    <link name="${prefix}_finger_${finger_id}_rubber_phalanx2_link">
        <visual>
            <origin xyz="0 0 0" rpy="0 0 0"/>
            <geometry>
                <mesh filename="package://alaris_gripper_description/meshes/Gripper_Assembly - rubber_phalanx_2.STL" scale="0.001 0.001 0.001"/>
            </geometry>
            <material name="black"/>
        </visual>
        <collision>
            <origin xyz="0.0 0.0 0.0" rpy="0 0 0"/>
            <geometry>
                <mesh filename="package://alaris_gripper_description/meshes/Gripper_Assembly - rubber_phalanx_2.STL" scale="0.001 0.001 0.001"/>
            </geometry>
        </collision>
        <inertial>
            <mass value="0.079" />
            <origin xyz="0 0 0" />
            <inertia ixx="0.003881243" ixy="0.0" ixz="0.0"
                     iyy="0.000498940" iyz="0.0"
                     izz="0.003879257" />
        </inertial>
    </link>

    <joint name="${prefix}_finger_${finger_id}_phalanx2_rubber_joint" type="fixed">
        <origin xyz="-0.0008 0.0008 0.0175" rpy="${PI/3} -${PI/7} ${PI/4}"/>
        <parent link="${prefix}_finger_${finger_id}_phalanx2_link"/>
        <child link="${prefix}_finger_${finger_id}_rubber_phalanx2_link"/>
    </joint>

    <link name="${prefix}_finger_${finger_id}_top_shaft1_link">
        <visual>
            <origin xyz="0 0 0" rpy="0 0 0"/>
            <geometry>
                <mesh filename="package://alaris_gripper_description/meshes/Gripper_Assembly - shaft_2.STL" scale="0.001 0.001 0.001"/>
            </geometry>
            <material name="gray"/>
        </visual>
        <collision>
            <origin xyz="0.0 0.0 0.0" rpy="0 0 0"/>
            <geometry>
                <mesh filename="package://alaris_gripper_description/meshes/Gripper_Assembly - shaft_2.STL" scale="0.001 0.001 0.001"/>
            </geometry>
        </collision>
        <inertial>
            <mass value="0.079" />
            <origin xyz="0 0 0" />
            <inertia ixx="0.003881243" ixy="0.0" ixz="0.0"
                     iyy="0.000498940" iyz="0.0"
                     izz="0.003879257" />
        </inertial>
    </link>

    <joint name="${prefix}_finger_${finger_id}_phalanx1_top_shaft1_joint" type="fixed">
        <origin xyz="0.00425 -0.0121 0.0414" rpy="0 0 -${PI/3}"/>
        <parent link="${prefix}_finger_${finger_id}_phalanx1_link"/>
        <child link="${prefix}_finger_${finger_id}_top_shaft1_link"/>
    </joint>

    <link name="${prefix}_finger_${finger_id}_bottom_shaft2_link">
        <visual>
            <origin xyz="0 0 0" rpy="0 0 0"/>
            <geometry>
                <mesh filename="package://alaris_gripper_description/meshes/Gripper_Assembly - shaft_4.STL" scale="0.001 0.001 0.001"/>
            </geometry>
            <material name="gray"/>
        </visual>
        <collision>
            <origin xyz="0.0 0.0 0.0" rpy="0 0 0"/>
            <geometry>
                <mesh filename="package://alaris_gripper_description/meshes/Gripper_Assembly - shaft_4.STL" scale="0.001 0.001 0.001"/>
            </geometry>
        </collision>
        <inertial>
            <mass value="0.079" />
            <origin xyz="0 0 0" />
            <inertia ixx="0.003881243" ixy="0.0" ixz="0.0"
                     iyy="0.000498940" iyz="0.0"
                     izz="0.003879257" />
        </inertial>
    </link>

    <joint name="${prefix}_finger_${finger_id}_link1_bottom_shaft2_joint" type="fixed">
        <origin xyz="0.01252 -0.0218 -0.0101" rpy="0 0 -${PI/3}"/>
        <parent link="${prefix}_finger_${finger_id}_link1_link"/>
        <child link="${prefix}_finger_${finger_id}_bottom_shaft2_link"/>
    </joint>

    <link name="${prefix}_finger_${finger_id}_top_shaft2_link">
        <visual>
            <origin xyz="0 0 0" rpy="0 0 0"/>
            <geometry>
                <mesh filename="package://alaris_gripper_description/meshes/Gripper_Assembly - shaft_5.STL" scale="0.001 0.001 0.001"/>
            </geometry>
            <material name="gray"/>
        </visual>
        <collision>
            <origin xyz="0.0 0.0 0.0" rpy="0 0 0"/>
            <geometry>
                <mesh filename="package://alaris_gripper_description/meshes/Gripper_Assembly - shaft_5.STL" scale="0.001 0.001 0.001"/>
            </geometry>
        </collision>
        <inertial>
            <mass value="0.079" />
            <origin xyz="0 0 0" />
            <inertia ixx="0.003881243" ixy="0.0" ixz="0.0"
                     iyy="0.000498940" iyz="0.0"
                     izz="0.003879257" />
        </inertial>
    </link>

    <joint name="${prefix}_finger_${finger_id}_phalanx2_top_shaft2_joint" type="fixed">
        <origin xyz="-0.00125 0.00325 -0.02835" rpy="0 0 -${PI/3}"/>
        <parent link="${prefix}_finger_${finger_id}_phalanx2_link"/>
        <child link="${prefix}_finger_${finger_id}_top_shaft2_link"/>
    </joint>


    <!-- Gazebo Related -->

     <gazebo>
        <plugin name="gazebo_ros_control" filename="libgazebo_ros_control.so">
          <robotNamespace>/</robotNamespace>
        </plugin>

        <plugin name="${prefix}_finger_${finger_id}_link1_bottom_shaft1_joint_plugin" filename="libroboticsgroup_gazebo_mimic_joint_plugin.so">
        <joint>${prefix}_mx28t_worm_joint</joint>
        <mimicJoint>${prefix}_finger_${finger_id}_link1_bottom_shaft1_joint</mimicJoint>
        <multiplier>1</multiplier>
        <offset>0</offset>
        <sensitiveness>0</sensitiveness>   <!-- if absolute difference between setpoint and process value is below this threshold, do nothing; 0.0 = disable [rad] -->
        <maxEffort>10</maxEffort> <!-- only taken into account if has_pid:=true [Nm] -->
        <robotNamespace>/</robotNamespace>
      </plugin>

        <plugin name="${prefix}_finger_${finger_id}_link1_revolution_point1_joint_plugin" filename="libroboticsgroup_gazebo_mimic_joint_plugin.so">
        <joint>${prefix}_finger_${finger_id}_phalanx2_revolution_point_joint</joint>
        <mimicJoint>${prefix}_finger_${finger_id}_link1_revolution_point1_joint</mimicJoint>
        <multiplier>0.49</multiplier>
        <offset>0</offset>
        <sensitiveness>0</sensitiveness>   <!-- if absolute difference between setpoint and process value is below this threshold, do nothing; 0.0 = disable [rad] -->
        <maxEffort>10</maxEffort> <!-- only taken into account if has_pid:=true [Nm] -->
        <robotNamespace>/</robotNamespace>
      </plugin>

        <plugin name="${prefix}_finger_${finger_id}_link1_revolution_point2_joint_plugin" filename="libroboticsgroup_gazebo_mimic_joint_plugin.so">
        <joint>${prefix}_finger_${finger_id}_phalanx2_revolution_point_joint</joint>
        <mimicJoint>${prefix}_finger_${finger_id}_link1_revolution_point2_joint</mimicJoint>
        <multiplier>-0.55</multiplier>
        <offset>0</offset>
        <sensitiveness>0</sensitiveness>   <!-- if absolute difference between setpoint and process value is below this threshold, do nothing; 0.0 = disable [rad] -->
        <maxEffort>10</maxEffort> <!-- only taken into account if has_pid:=true [Nm] -->
        <robotNamespace>/</robotNamespace>
      </plugin>
    </gazebo>

    <transmission name="${prefix}_finger_${finger_id}_phalanx2_revolution_point_trans" type="SimpleTransmission">
        <type>transmission_interface/SimpleTransmission</type>
        <actuator name="${prefix}_finger_${finger_id}_phalanx2_revolution_point_motor">
            <mechanicalReduction>1</mechanicalReduction>
        </actuator>
        <joint name="${prefix}_finger_${finger_id}_phalanx2_revolution_point_joint">
            <hardwareInterface>hardware_interface/EffortJointInterface</hardwareInterface>
        </joint>
    </transmission>

    <gazebo reference="${prefix}_finger_${finger_id}_bottom_shaft1_link">
      <self_collide>false</self_collide>
    </gazebo>
    <gazebo reference="${prefix}_finger_${finger_id}_link1_revolution_point1">
      <self_collide>false</self_collide>
    </gazebo>
    <gazebo reference="${prefix}_finger_${finger_id}_link1_link">
      <self_collide>false</self_collide>
    </gazebo>
    <gazebo reference="${prefix}_finger_${finger_id}_link1_revolution_point2">
      <self_collide>false</self_collide>
    </gazebo>
    <gazebo reference="${prefix}_finger_${finger_id}_link2_link">
      <self_collide>false</self_collide>
    </gazebo>
    <gazebo reference="${prefix}_finger_${finger_id}_phalanx1_link">
      <self_collide>false</self_collide>
    </gazebo>
    <gazebo reference="${prefix}_finger_${finger_id}_phalanx2_revolution_point">
      <self_collide>false</self_collide>
    </gazebo>
    <gazebo reference="${prefix}_finger_${finger_id}_phalanx2_link">
      <self_collide>false</self_collide>
    </gazebo>
    <gazebo reference="${prefix}_finger_${finger_id}_rubber_phalanx1_link">
      <self_collide>false</self_collide>
    </gazebo>
    <gazebo reference="${prefix}_finger_${finger_id}_rubber_phalanx2_link">
      <self_collide>false</self_collide>
    </gazebo>
    <gazebo reference="${prefix}_finger_${finger_id}_top_shaft1_link">
      <self_collide>false</self_collide>
    </gazebo>
    <gazebo reference="${prefix}_finger_${finger_id}_bottom_shaft2_link">
      <self_collide>false</self_collide>
    </gazebo>
    <gazebo reference="${prefix}_finger_${finger_id}_top_shaft2_link">
      <self_collide>false</self_collide>
    </gazebo>

</xacro:macro>

</robot>
